<?xml version="1.0" encoding="UTF-8"?>
<testng-results retried="4" ignored="0" total="8" passed="2" failed="2" skipped="0">
  <reporter-output>
  </reporter-output>
  <suite started-at="2021-04-20T18:17:11 IST" name="Suite" finished-at="2021-04-20T18:20:04 IST" duration-ms="172840">
    <groups>
    </groups>
    <test started-at="2021-04-20T18:17:11 IST" name="Test" finished-at="2021-04-20T18:20:04 IST" duration-ms="172840">
      <class name="com.athmatest.qa.testcases.SampleTest">
        <test-method is-config="true" signature="intialization()[pri:0, instance:com.athmatest.qa.testcases.SampleTest@37afeb11]" started-at="2021-04-20T18:17:11 IST" name="intialization" finished-at="2021-04-20T18:17:26 IST" duration-ms="14456" status="PASS">
          <reporter-output>
          </reporter-output>
        </test-method> <!-- intialization -->
        <test-method is-config="true" signature="loginToTheApplication()[pri:0, instance:com.athmatest.qa.testcases.SampleTest@37afeb11]" started-at="2021-04-20T18:17:26 IST" name="loginToTheApplication" finished-at="2021-04-20T18:17:32 IST" duration-ms="6443" status="PASS">
          <reporter-output>
          </reporter-output>
        </test-method> <!-- loginToTheApplication -->
        <test-method signature="myFirstTest()[pri:1, instance:com.athmatest.qa.testcases.SampleTest@37afeb11]" started-at="2021-04-20T18:17:32 IST" name="myFirstTest" finished-at="2021-04-20T18:17:32 IST" duration-ms="38" status="PASS">
          <reporter-output>
          </reporter-output>
        </test-method> <!-- myFirstTest -->
        <test-method is-config="true" signature="logOutFromTheApplication()[pri:0, instance:com.athmatest.qa.testcases.SampleTest@37afeb11]" started-at="2021-04-20T18:17:32 IST" name="logOutFromTheApplication" finished-at="2021-04-20T18:17:39 IST" duration-ms="6682" status="PASS">
          <reporter-output>
          </reporter-output>
        </test-method> <!-- logOutFromTheApplication -->
        <test-method is-config="true" signature="loginToTheApplication()[pri:0, instance:com.athmatest.qa.testcases.SampleTest@37afeb11]" started-at="2021-04-20T18:17:39 IST" name="loginToTheApplication" finished-at="2021-04-20T18:17:45 IST" duration-ms="6309" status="PASS">
          <reporter-output>
          </reporter-output>
        </test-method> <!-- loginToTheApplication -->
        <test-method signature="mySecondTest()[pri:2, instance:com.athmatest.qa.testcases.SampleTest@37afeb11]" started-at="2021-04-20T18:17:45 IST" name="mySecondTest" finished-at="2021-04-20T18:17:52 IST" duration-ms="6438" status="PASS">
          <reporter-output>
          </reporter-output>
        </test-method> <!-- mySecondTest -->
        <test-method is-config="true" signature="logOutFromTheApplication()[pri:0, instance:com.athmatest.qa.testcases.SampleTest@37afeb11]" started-at="2021-04-20T18:17:52 IST" name="logOutFromTheApplication" finished-at="2021-04-20T18:17:58 IST" duration-ms="6284" status="PASS">
          <reporter-output>
          </reporter-output>
        </test-method> <!-- logOutFromTheApplication -->
        <test-method is-config="true" signature="loginToTheApplication()[pri:0, instance:com.athmatest.qa.testcases.SampleTest@37afeb11]" started-at="2021-04-20T18:17:58 IST" name="loginToTheApplication" finished-at="2021-04-20T18:18:04 IST" duration-ms="6277" status="PASS">
          <reporter-output>
          </reporter-output>
        </test-method> <!-- loginToTheApplication -->
        <test-method retried="true" signature="myThirdTest()[pri:3, instance:com.athmatest.qa.testcases.SampleTest@37afeb11]" started-at="2021-04-20T18:18:04 IST" name="myThirdTest" finished-at="2021-04-20T18:18:17 IST" duration-ms="12517" status="SKIP">
          <exception class="java.lang.AssertionError">
            <message>
              <![CDATA[expected [true] but found [false]]]>
            </message>
            <full-stacktrace>
              <![CDATA[java.lang.AssertionError: expected [true] but found [false]
at org.testng.Assert.fail(Assert.java:99)
at org.testng.Assert.failNotEquals(Assert.java:1037)
at org.testng.Assert.assertEqualsImpl(Assert.java:140)
at org.testng.Assert.assertEquals(Assert.java:122)
at org.testng.Assert.assertEquals(Assert.java:819)
at org.testng.Assert.assertEquals(Assert.java:829)
at com.athmatest.qa.testcases.SampleTest.myThirdTest(SampleTest.java:51)
at java.base/jdk.internal.reflect.NativeMethodAccessorImpl.invoke0(Native Method)
at java.base/jdk.internal.reflect.NativeMethodAccessorImpl.invoke(NativeMethodAccessorImpl.java:64)
at java.base/jdk.internal.reflect.DelegatingMethodAccessorImpl.invoke(DelegatingMethodAccessorImpl.java:43)
at java.base/java.lang.reflect.Method.invoke(Method.java:564)
at org.testng.internal.MethodInvocationHelper.invokeMethod(MethodInvocationHelper.java:133)
at org.testng.internal.TestInvoker.invokeMethod(TestInvoker.java:598)
at org.testng.internal.TestInvoker.invokeTestMethod(TestInvoker.java:173)
at org.testng.internal.MethodRunner.runInSequence(MethodRunner.java:46)
at org.testng.internal.TestInvoker$MethodInvocationAgent.invoke(TestInvoker.java:824)
at org.testng.internal.TestInvoker.invokeTestMethods(TestInvoker.java:146)
at org.testng.internal.TestMethodWorker.invokeTestMethods(TestMethodWorker.java:146)
at org.testng.internal.TestMethodWorker.run(TestMethodWorker.java:128)
at java.base/java.util.ArrayList.forEach(ArrayList.java:1511)
at org.testng.TestRunner.privateRun(TestRunner.java:794)
at org.testng.TestRunner.run(TestRunner.java:596)
at org.testng.SuiteRunner.runTest(SuiteRunner.java:377)
at org.testng.SuiteRunner.runSequentially(SuiteRunner.java:371)
at org.testng.SuiteRunner.privateRun(SuiteRunner.java:332)
at org.testng.SuiteRunner.run(SuiteRunner.java:276)
at org.testng.SuiteRunnerWorker.runSuite(SuiteRunnerWorker.java:53)
at org.testng.SuiteRunnerWorker.run(SuiteRunnerWorker.java:96)
at org.testng.TestNG.runSuitesSequentially(TestNG.java:1212)
at org.testng.TestNG.runSuitesLocally(TestNG.java:1134)
at org.testng.TestNG.runSuites(TestNG.java:1063)
at org.testng.TestNG.run(TestNG.java:1031)
at org.testng.remote.AbstractRemoteTestNG.run(AbstractRemoteTestNG.java:115)
at org.testng.remote.RemoteTestNG.initAndRun(RemoteTestNG.java:251)
at org.testng.remote.RemoteTestNG.main(RemoteTestNG.java:77)
]]>
            </full-stacktrace>
          </exception> <!-- java.lang.AssertionError -->
          <reporter-output>
          </reporter-output>
        </test-method> <!-- myThirdTest -->
        <test-method is-config="true" signature="logOutFromTheApplication()[pri:0, instance:com.athmatest.qa.testcases.SampleTest@37afeb11]" started-at="2021-04-20T18:18:17 IST" name="logOutFromTheApplication" finished-at="2021-04-20T18:18:24 IST" duration-ms="6641" status="PASS">
          <reporter-output>
          </reporter-output>
        </test-method> <!-- logOutFromTheApplication -->
        <test-method is-config="true" signature="loginToTheApplication()[pri:0, instance:com.athmatest.qa.testcases.SampleTest@37afeb11]" started-at="2021-04-20T18:18:24 IST" name="loginToTheApplication" finished-at="2021-04-20T18:18:30 IST" duration-ms="6269" status="PASS">
          <reporter-output>
          </reporter-output>
        </test-method> <!-- loginToTheApplication -->
        <test-method retried="true" signature="myThirdTest()[pri:3, instance:com.athmatest.qa.testcases.SampleTest@37afeb11]" started-at="2021-04-20T18:18:30 IST" name="myThirdTest" finished-at="2021-04-20T18:18:38 IST" duration-ms="8323" status="SKIP">
          <exception class="java.lang.AssertionError">
            <message>
              <![CDATA[expected [true] but found [false]]]>
            </message>
            <full-stacktrace>
              <![CDATA[java.lang.AssertionError: expected [true] but found [false]
at org.testng.Assert.fail(Assert.java:99)
at org.testng.Assert.failNotEquals(Assert.java:1037)
at org.testng.Assert.assertEqualsImpl(Assert.java:140)
at org.testng.Assert.assertEquals(Assert.java:122)
at org.testng.Assert.assertEquals(Assert.java:819)
at org.testng.Assert.assertEquals(Assert.java:829)
at com.athmatest.qa.testcases.SampleTest.myThirdTest(SampleTest.java:51)
at java.base/jdk.internal.reflect.NativeMethodAccessorImpl.invoke0(Native Method)
at java.base/jdk.internal.reflect.NativeMethodAccessorImpl.invoke(NativeMethodAccessorImpl.java:64)
at java.base/jdk.internal.reflect.DelegatingMethodAccessorImpl.invoke(DelegatingMethodAccessorImpl.java:43)
at java.base/java.lang.reflect.Method.invoke(Method.java:564)
at org.testng.internal.MethodInvocationHelper.invokeMethod(MethodInvocationHelper.java:133)
at org.testng.internal.TestInvoker.invokeMethod(TestInvoker.java:598)
at org.testng.internal.TestInvoker.retryFailed(TestInvoker.java:213)
at org.testng.internal.MethodRunner.runInSequence(MethodRunner.java:58)
at org.testng.internal.TestInvoker$MethodInvocationAgent.invoke(TestInvoker.java:824)
at org.testng.internal.TestInvoker.invokeTestMethods(TestInvoker.java:146)
at org.testng.internal.TestMethodWorker.invokeTestMethods(TestMethodWorker.java:146)
at org.testng.internal.TestMethodWorker.run(TestMethodWorker.java:128)
at java.base/java.util.ArrayList.forEach(ArrayList.java:1511)
at org.testng.TestRunner.privateRun(TestRunner.java:794)
at org.testng.TestRunner.run(TestRunner.java:596)
at org.testng.SuiteRunner.runTest(SuiteRunner.java:377)
at org.testng.SuiteRunner.runSequentially(SuiteRunner.java:371)
at org.testng.SuiteRunner.privateRun(SuiteRunner.java:332)
at org.testng.SuiteRunner.run(SuiteRunner.java:276)
at org.testng.SuiteRunnerWorker.runSuite(SuiteRunnerWorker.java:53)
at org.testng.SuiteRunnerWorker.run(SuiteRunnerWorker.java:96)
at org.testng.TestNG.runSuitesSequentially(TestNG.java:1212)
at org.testng.TestNG.runSuitesLocally(TestNG.java:1134)
at org.testng.TestNG.runSuites(TestNG.java:1063)
at org.testng.TestNG.run(TestNG.java:1031)
at org.testng.remote.AbstractRemoteTestNG.run(AbstractRemoteTestNG.java:115)
at org.testng.remote.RemoteTestNG.initAndRun(RemoteTestNG.java:251)
at org.testng.remote.RemoteTestNG.main(RemoteTestNG.java:77)
]]>
            </full-stacktrace>
          </exception> <!-- java.lang.AssertionError -->
          <reporter-output>
          </reporter-output>
        </test-method> <!-- myThirdTest -->
        <test-method is-config="true" signature="logOutFromTheApplication()[pri:0, instance:com.athmatest.qa.testcases.SampleTest@37afeb11]" started-at="2021-04-20T18:18:38 IST" name="logOutFromTheApplication" finished-at="2021-04-20T18:18:45 IST" duration-ms="6336" status="PASS">
          <reporter-output>
          </reporter-output>
        </test-method> <!-- logOutFromTheApplication -->
        <test-method is-config="true" signature="loginToTheApplication()[pri:0, instance:com.athmatest.qa.testcases.SampleTest@37afeb11]" started-at="2021-04-20T18:18:45 IST" name="loginToTheApplication" finished-at="2021-04-20T18:18:51 IST" duration-ms="6341" status="PASS">
          <reporter-output>
          </reporter-output>
        </test-method> <!-- loginToTheApplication -->
        <test-method signature="myThirdTest()[pri:3, instance:com.athmatest.qa.testcases.SampleTest@37afeb11]" started-at="2021-04-20T18:18:51 IST" name="myThirdTest" finished-at="2021-04-20T18:18:58 IST" duration-ms="7142" status="FAIL">
          <exception class="java.lang.AssertionError">
            <message>
              <![CDATA[expected [true] but found [false]]]>
            </message>
            <full-stacktrace>
              <![CDATA[java.lang.AssertionError: expected [true] but found [false]
at org.testng.Assert.fail(Assert.java:99)
at org.testng.Assert.failNotEquals(Assert.java:1037)
at org.testng.Assert.assertEqualsImpl(Assert.java:140)
at org.testng.Assert.assertEquals(Assert.java:122)
at org.testng.Assert.assertEquals(Assert.java:819)
at org.testng.Assert.assertEquals(Assert.java:829)
at com.athmatest.qa.testcases.SampleTest.myThirdTest(SampleTest.java:51)
at java.base/jdk.internal.reflect.NativeMethodAccessorImpl.invoke0(Native Method)
at java.base/jdk.internal.reflect.NativeMethodAccessorImpl.invoke(NativeMethodAccessorImpl.java:64)
at java.base/jdk.internal.reflect.DelegatingMethodAccessorImpl.invoke(DelegatingMethodAccessorImpl.java:43)
at java.base/java.lang.reflect.Method.invoke(Method.java:564)
at org.testng.internal.MethodInvocationHelper.invokeMethod(MethodInvocationHelper.java:133)
at org.testng.internal.TestInvoker.invokeMethod(TestInvoker.java:598)
at org.testng.internal.TestInvoker.retryFailed(TestInvoker.java:213)
at org.testng.internal.MethodRunner.runInSequence(MethodRunner.java:58)
at org.testng.internal.TestInvoker$MethodInvocationAgent.invoke(TestInvoker.java:824)
at org.testng.internal.TestInvoker.invokeTestMethods(TestInvoker.java:146)
at org.testng.internal.TestMethodWorker.invokeTestMethods(TestMethodWorker.java:146)
at org.testng.internal.TestMethodWorker.run(TestMethodWorker.java:128)
at java.base/java.util.ArrayList.forEach(ArrayList.java:1511)
at org.testng.TestRunner.privateRun(TestRunner.java:794)
at org.testng.TestRunner.run(TestRunner.java:596)
at org.testng.SuiteRunner.runTest(SuiteRunner.java:377)
at org.testng.SuiteRunner.runSequentially(SuiteRunner.java:371)
at org.testng.SuiteRunner.privateRun(SuiteRunner.java:332)
at org.testng.SuiteRunner.run(SuiteRunner.java:276)
at org.testng.SuiteRunnerWorker.runSuite(SuiteRunnerWorker.java:53)
at org.testng.SuiteRunnerWorker.run(SuiteRunnerWorker.java:96)
at org.testng.TestNG.runSuitesSequentially(TestNG.java:1212)
at org.testng.TestNG.runSuitesLocally(TestNG.java:1134)
at org.testng.TestNG.runSuites(TestNG.java:1063)
at org.testng.TestNG.run(TestNG.java:1031)
at org.testng.remote.AbstractRemoteTestNG.run(AbstractRemoteTestNG.java:115)
at org.testng.remote.RemoteTestNG.initAndRun(RemoteTestNG.java:251)
at org.testng.remote.RemoteTestNG.main(RemoteTestNG.java:77)
]]>
            </full-stacktrace>
          </exception> <!-- java.lang.AssertionError -->
          <reporter-output>
          </reporter-output>
        </test-method> <!-- myThirdTest -->
        <test-method is-config="true" signature="logOutFromTheApplication()[pri:0, instance:com.athmatest.qa.testcases.SampleTest@37afeb11]" started-at="2021-04-20T18:18:58 IST" name="logOutFromTheApplication" finished-at="2021-04-20T18:19:04 IST" duration-ms="6224" status="PASS">
          <reporter-output>
          </reporter-output>
        </test-method> <!-- logOutFromTheApplication -->
        <test-method is-config="true" signature="loginToTheApplication()[pri:0, instance:com.athmatest.qa.testcases.SampleTest@37afeb11]" started-at="2021-04-20T18:19:04 IST" name="loginToTheApplication" finished-at="2021-04-20T18:19:11 IST" duration-ms="6282" status="PASS">
          <reporter-output>
          </reporter-output>
        </test-method> <!-- loginToTheApplication -->
        <test-method retried="true" signature="myFourthTest()[pri:4, instance:com.athmatest.qa.testcases.SampleTest@37afeb11]" started-at="2021-04-20T18:19:11 IST" name="myFourthTest" finished-at="2021-04-20T18:19:18 IST" duration-ms="7480" status="SKIP">
          <exception class="java.lang.AssertionError">
            <message>
              <![CDATA[expected [true] but found [false]]]>
            </message>
            <full-stacktrace>
              <![CDATA[java.lang.AssertionError: expected [true] but found [false]
at org.testng.Assert.fail(Assert.java:99)
at org.testng.Assert.failNotEquals(Assert.java:1037)
at org.testng.Assert.assertEqualsImpl(Assert.java:140)
at org.testng.Assert.assertEquals(Assert.java:122)
at org.testng.Assert.assertEquals(Assert.java:819)
at org.testng.Assert.assertEquals(Assert.java:829)
at com.athmatest.qa.testcases.SampleTest.myFourthTest(SampleTest.java:58)
at java.base/jdk.internal.reflect.NativeMethodAccessorImpl.invoke0(Native Method)
at java.base/jdk.internal.reflect.NativeMethodAccessorImpl.invoke(NativeMethodAccessorImpl.java:64)
at java.base/jdk.internal.reflect.DelegatingMethodAccessorImpl.invoke(DelegatingMethodAccessorImpl.java:43)
at java.base/java.lang.reflect.Method.invoke(Method.java:564)
at org.testng.internal.MethodInvocationHelper.invokeMethod(MethodInvocationHelper.java:133)
at org.testng.internal.TestInvoker.invokeMethod(TestInvoker.java:598)
at org.testng.internal.TestInvoker.invokeTestMethod(TestInvoker.java:173)
at org.testng.internal.MethodRunner.runInSequence(MethodRunner.java:46)
at org.testng.internal.TestInvoker$MethodInvocationAgent.invoke(TestInvoker.java:824)
at org.testng.internal.TestInvoker.invokeTestMethods(TestInvoker.java:146)
at org.testng.internal.TestMethodWorker.invokeTestMethods(TestMethodWorker.java:146)
at org.testng.internal.TestMethodWorker.run(TestMethodWorker.java:128)
at java.base/java.util.ArrayList.forEach(ArrayList.java:1511)
at org.testng.TestRunner.privateRun(TestRunner.java:794)
at org.testng.TestRunner.run(TestRunner.java:596)
at org.testng.SuiteRunner.runTest(SuiteRunner.java:377)
at org.testng.SuiteRunner.runSequentially(SuiteRunner.java:371)
at org.testng.SuiteRunner.privateRun(SuiteRunner.java:332)
at org.testng.SuiteRunner.run(SuiteRunner.java:276)
at org.testng.SuiteRunnerWorker.runSuite(SuiteRunnerWorker.java:53)
at org.testng.SuiteRunnerWorker.run(SuiteRunnerWorker.java:96)
at org.testng.TestNG.runSuitesSequentially(TestNG.java:1212)
at org.testng.TestNG.runSuitesLocally(TestNG.java:1134)
at org.testng.TestNG.runSuites(TestNG.java:1063)
at org.testng.TestNG.run(TestNG.java:1031)
at org.testng.remote.AbstractRemoteTestNG.run(AbstractRemoteTestNG.java:115)
at org.testng.remote.RemoteTestNG.initAndRun(RemoteTestNG.java:251)
at org.testng.remote.RemoteTestNG.main(RemoteTestNG.java:77)
]]>
            </full-stacktrace>
          </exception> <!-- java.lang.AssertionError -->
          <reporter-output>
          </reporter-output>
        </test-method> <!-- myFourthTest -->
        <test-method is-config="true" signature="logOutFromTheApplication()[pri:0, instance:com.athmatest.qa.testcases.SampleTest@37afeb11]" started-at="2021-04-20T18:19:18 IST" name="logOutFromTheApplication" finished-at="2021-04-20T18:19:24 IST" duration-ms="6271" status="PASS">
          <reporter-output>
          </reporter-output>
        </test-method> <!-- logOutFromTheApplication -->
        <test-method is-config="true" signature="loginToTheApplication()[pri:0, instance:com.athmatest.qa.testcases.SampleTest@37afeb11]" started-at="2021-04-20T18:19:24 IST" name="loginToTheApplication" finished-at="2021-04-20T18:19:31 IST" duration-ms="6229" status="PASS">
          <reporter-output>
          </reporter-output>
        </test-method> <!-- loginToTheApplication -->
        <test-method retried="true" signature="myFourthTest()[pri:4, instance:com.athmatest.qa.testcases.SampleTest@37afeb11]" started-at="2021-04-20T18:19:31 IST" name="myFourthTest" finished-at="2021-04-20T18:19:38 IST" duration-ms="7317" status="SKIP">
          <exception class="java.lang.AssertionError">
            <message>
              <![CDATA[expected [true] but found [false]]]>
            </message>
            <full-stacktrace>
              <![CDATA[java.lang.AssertionError: expected [true] but found [false]
at org.testng.Assert.fail(Assert.java:99)
at org.testng.Assert.failNotEquals(Assert.java:1037)
at org.testng.Assert.assertEqualsImpl(Assert.java:140)
at org.testng.Assert.assertEquals(Assert.java:122)
at org.testng.Assert.assertEquals(Assert.java:819)
at org.testng.Assert.assertEquals(Assert.java:829)
at com.athmatest.qa.testcases.SampleTest.myFourthTest(SampleTest.java:58)
at java.base/jdk.internal.reflect.NativeMethodAccessorImpl.invoke0(Native Method)
at java.base/jdk.internal.reflect.NativeMethodAccessorImpl.invoke(NativeMethodAccessorImpl.java:64)
at java.base/jdk.internal.reflect.DelegatingMethodAccessorImpl.invoke(DelegatingMethodAccessorImpl.java:43)
at java.base/java.lang.reflect.Method.invoke(Method.java:564)
at org.testng.internal.MethodInvocationHelper.invokeMethod(MethodInvocationHelper.java:133)
at org.testng.internal.TestInvoker.invokeMethod(TestInvoker.java:598)
at org.testng.internal.TestInvoker.retryFailed(TestInvoker.java:213)
at org.testng.internal.MethodRunner.runInSequence(MethodRunner.java:58)
at org.testng.internal.TestInvoker$MethodInvocationAgent.invoke(TestInvoker.java:824)
at org.testng.internal.TestInvoker.invokeTestMethods(TestInvoker.java:146)
at org.testng.internal.TestMethodWorker.invokeTestMethods(TestMethodWorker.java:146)
at org.testng.internal.TestMethodWorker.run(TestMethodWorker.java:128)
at java.base/java.util.ArrayList.forEach(ArrayList.java:1511)
at org.testng.TestRunner.privateRun(TestRunner.java:794)
at org.testng.TestRunner.run(TestRunner.java:596)
at org.testng.SuiteRunner.runTest(SuiteRunner.java:377)
at org.testng.SuiteRunner.runSequentially(SuiteRunner.java:371)
at org.testng.SuiteRunner.privateRun(SuiteRunner.java:332)
at org.testng.SuiteRunner.run(SuiteRunner.java:276)
at org.testng.SuiteRunnerWorker.runSuite(SuiteRunnerWorker.java:53)
at org.testng.SuiteRunnerWorker.run(SuiteRunnerWorker.java:96)
at org.testng.TestNG.runSuitesSequentially(TestNG.java:1212)
at org.testng.TestNG.runSuitesLocally(TestNG.java:1134)
at org.testng.TestNG.runSuites(TestNG.java:1063)
at org.testng.TestNG.run(TestNG.java:1031)
at org.testng.remote.AbstractRemoteTestNG.run(AbstractRemoteTestNG.java:115)
at org.testng.remote.RemoteTestNG.initAndRun(RemoteTestNG.java:251)
at org.testng.remote.RemoteTestNG.main(RemoteTestNG.java:77)
]]>
            </full-stacktrace>
          </exception> <!-- java.lang.AssertionError -->
          <reporter-output>
          </reporter-output>
        </test-method> <!-- myFourthTest -->
        <test-method is-config="true" signature="logOutFromTheApplication()[pri:0, instance:com.athmatest.qa.testcases.SampleTest@37afeb11]" started-at="2021-04-20T18:19:38 IST" name="logOutFromTheApplication" finished-at="2021-04-20T18:19:44 IST" duration-ms="6249" status="PASS">
          <reporter-output>
          </reporter-output>
        </test-method> <!-- logOutFromTheApplication -->
        <test-method is-config="true" signature="loginToTheApplication()[pri:0, instance:com.athmatest.qa.testcases.SampleTest@37afeb11]" started-at="2021-04-20T18:19:44 IST" name="loginToTheApplication" finished-at="2021-04-20T18:19:50 IST" duration-ms="6290" status="PASS">
          <reporter-output>
          </reporter-output>
        </test-method> <!-- loginToTheApplication -->
        <test-method signature="myFourthTest()[pri:4, instance:com.athmatest.qa.testcases.SampleTest@37afeb11]" started-at="2021-04-20T18:19:50 IST" name="myFourthTest" finished-at="2021-04-20T18:19:57 IST" duration-ms="7071" status="FAIL">
          <exception class="java.lang.AssertionError">
            <message>
              <![CDATA[expected [true] but found [false]]]>
            </message>
            <full-stacktrace>
              <![CDATA[java.lang.AssertionError: expected [true] but found [false]
at org.testng.Assert.fail(Assert.java:99)
at org.testng.Assert.failNotEquals(Assert.java:1037)
at org.testng.Assert.assertEqualsImpl(Assert.java:140)
at org.testng.Assert.assertEquals(Assert.java:122)
at org.testng.Assert.assertEquals(Assert.java:819)
at org.testng.Assert.assertEquals(Assert.java:829)
at com.athmatest.qa.testcases.SampleTest.myFourthTest(SampleTest.java:58)
at java.base/jdk.internal.reflect.NativeMethodAccessorImpl.invoke0(Native Method)
at java.base/jdk.internal.reflect.NativeMethodAccessorImpl.invoke(NativeMethodAccessorImpl.java:64)
at java.base/jdk.internal.reflect.DelegatingMethodAccessorImpl.invoke(DelegatingMethodAccessorImpl.java:43)
at java.base/java.lang.reflect.Method.invoke(Method.java:564)
at org.testng.internal.MethodInvocationHelper.invokeMethod(MethodInvocationHelper.java:133)
at org.testng.internal.TestInvoker.invokeMethod(TestInvoker.java:598)
at org.testng.internal.TestInvoker.retryFailed(TestInvoker.java:213)
at org.testng.internal.MethodRunner.runInSequence(MethodRunner.java:58)
at org.testng.internal.TestInvoker$MethodInvocationAgent.invoke(TestInvoker.java:824)
at org.testng.internal.TestInvoker.invokeTestMethods(TestInvoker.java:146)
at org.testng.internal.TestMethodWorker.invokeTestMethods(TestMethodWorker.java:146)
at org.testng.internal.TestMethodWorker.run(TestMethodWorker.java:128)
at java.base/java.util.ArrayList.forEach(ArrayList.java:1511)
at org.testng.TestRunner.privateRun(TestRunner.java:794)
at org.testng.TestRunner.run(TestRunner.java:596)
at org.testng.SuiteRunner.runTest(SuiteRunner.java:377)
at org.testng.SuiteRunner.runSequentially(SuiteRunner.java:371)
at org.testng.SuiteRunner.privateRun(SuiteRunner.java:332)
at org.testng.SuiteRunner.run(SuiteRunner.java:276)
at org.testng.SuiteRunnerWorker.runSuite(SuiteRunnerWorker.java:53)
at org.testng.SuiteRunnerWorker.run(SuiteRunnerWorker.java:96)
at org.testng.TestNG.runSuitesSequentially(TestNG.java:1212)
at org.testng.TestNG.runSuitesLocally(TestNG.java:1134)
at org.testng.TestNG.runSuites(TestNG.java:1063)
at org.testng.TestNG.run(TestNG.java:1031)
at org.testng.remote.AbstractRemoteTestNG.run(AbstractRemoteTestNG.java:115)
at org.testng.remote.RemoteTestNG.initAndRun(RemoteTestNG.java:251)
at org.testng.remote.RemoteTestNG.main(RemoteTestNG.java:77)
]]>
            </full-stacktrace>
          </exception> <!-- java.lang.AssertionError -->
          <reporter-output>
          </reporter-output>
        </test-method> <!-- myFourthTest -->
        <test-method is-config="true" signature="logOutFromTheApplication()[pri:0, instance:com.athmatest.qa.testcases.SampleTest@37afeb11]" started-at="2021-04-20T18:19:57 IST" name="logOutFromTheApplication" finished-at="2021-04-20T18:20:04 IST" duration-ms="6222" status="PASS">
          <reporter-output>
          </reporter-output>
        </test-method> <!-- logOutFromTheApplication -->
        <test-method is-config="true" signature="closeBrowser()[pri:0, instance:com.athmatest.qa.testcases.SampleTest@37afeb11]" started-at="2021-04-20T18:20:04 IST" name="closeBrowser" finished-at="2021-04-20T18:20:04 IST" duration-ms="605" status="PASS">
          <reporter-output>
          </reporter-output>
        </test-method> <!-- closeBrowser -->
      </class> <!-- com.athmatest.qa.testcases.SampleTest -->
    </test> <!-- Test -->
  </suite> <!-- Suite -->
</testng-results>
